Workbook

Sheet Prospetto A3
A1: PROSPETTO ATTIVITÀ COMMERCIALE PUBBLICO — aggiornato al 10 settembre 2026
B2: ENTE | C2: DESCRIZIONE | D2: IMPORTO (€) | E2: LOTTI | J2: SOPRALLUOGO | K2: SCADENZA | L2: APERTURA | N2: DURATA | P2: PROGETTISTA | Q2: COSTO PROGETTO (€) | R2: ALTRI COSTI (fideiuss., ecc.) | S2: ATI | T2: NOTE | U2: LINK | V2: ESITO | W2: ID GARA | X2: CIG
E3: TOT | F3: PART | G3: AGG | H3: PAR.TI | I3: VALORE PART.TI | L3: TECNICO | M3: ECONOMICO | N3: CONVENZ. | O3: CONTRATTO
A4: PASSATE (1 procedura)
A5: =HYPERLINK("F:\Appalti\Stadio San Siro","Apri") -> Apri | B5: STADIO SAN SIRO | C5: CONCESSIONE | D5: 197075590 | T5: Comune di Milano — Avviso pubblico 24/03/2025 (rogito firmato 05/11/2025) | U5: Comune Milano - Avviso San Siro | W5: Avviso pubblico DD 2213 del 24/03/2025 — Rogito Rep. notarile 77207/2025 | X5: D.Lgs. 38/2021 art. 4 c.13 (Legge Stadi)
A6: IN VALUTAZIONE (4 procedure)
A7: =HYPERLINK("F:\Appalti\Comune di Alghero","Apri") -> Apri | B7: COMUNE DI ALGHERO | C7: PPP TERMICO E PUBBLICA ILLUM | D7: 33835000 | E7: 1 | F7: 1 | G7: 1 | H7: 1 | I7: 33835000 | J7: SI | K7: 46136 | N7: / | O7: 20A | P7: INGEIA | Q7: NON SOSTENUTI DA CS | R7: NON SOSTENUTI DA CS | S7: RENOVIT 55% - GETEC 45% | T7: 20% SUBAPPALATO PASSANTE PER CS | U7: Portale appalti Alghero | W7: TBD — bando non ancora pubblicato su portale Maggioli (vedi anomalia QualEnergia 27/02/2026) | X7: —
A8: =HYPERLINK("F:\Appalti\Aria Manutenzione Impianti Elettrici Sanità","Apri") -> Apri | B8: ARIA | C8: MANUTENZIONE IMP. ELETTRICI SANITA' PR. AP. ART 71 | D8: 12751568 | E8: 7 | F8: 7 | G8: 7 | H8: 3 4 6 | I8: 9756650 | J8: NO | K8: 46160 | L8: 46162 | N8: / | O8: 36M | P8: MENS | Q8: 14750 | R8: DA QUANTIFICARE | S8: CONSORZIO INNOVA | T8: C.INNOVA INDICA 100% CS; COSTI PROGETTO COMPENSATI | W8: ARIA_2026_401 — Piattaforma Sintel — RUP Carmen Schweigl | X8: vedi all. Dettaglio Lotti (7 CIG, uno per lotto)
A9: =HYPERLINK("F:\Appalti\Aria Manutenzione Impianti Idrici","Apri") -> Apri | B9: ARIA | C9: MANUTEZIONE IMP.IDRICI PR. AP.ART71 | D9: 5960717.4 | E9: 6 | F9: 6 | G9: 6 | H9: 1 2 | I9: 4981384 | J9: NO | K9: 46168 | L9: 46177 | N9: / | O9: 36M | P9: MENS | Q9: COMPRENSO NEI 14,7K | R9: DA QUANTIFICARE | S9: CONSORZIO INNOVA | T9: C.INNOVA INDICA 100% CS; COSTI PROGETTO COMPENSATI | W9: ARIA_2026_410 — Piattaforma Sintel — Bando GUUE 276431-2026 | X9: vedi all. Dettaglio Lotti (6 CIG, uno per lotto)
A10: =HYPERLINK("F:\Appalti\Consip SIE PAL ID 2849","Apri") -> Apri | B10: CONSIP | C10: AQ SERVIZIO INTEGRATO ENERGIA PAL | D10: 2015086959 | E10: 10 | F10: 7 | G10: 7 | H10: 2 3 6 7 8 9 10 | I10: 1032130000 | J10: NO | K10: 46147 | N10: 36M | O10: 3/6 ANNI | P10: INGEIA | Q10: 226070 | R10: 14923.28 | S10: RENOVIT/ TEKAL/ CECCHINI/ CERTOSA10% | W10: Consip ID 2849 — AQ SIE PAL — Bando GUUE S 051 del 13/03/2026 | X10: vedi Bando UE — 10 CIG, uno per lotto territoriale
A11: IN CORSO (2 procedure)
A12: =HYPERLINK("F:\Appalti\ASP Pavia EPC","Apri") -> Apri | B12: ASP PAVIA | C12: EPC | D12: 21665189 | E12: 1 | F12: 1 | G12: 1 | H12: 1 | J12: SI | K12: 46195 | N12: / | O12: 12 | P12: MENS | Q12: 35500 | R12: DA QUANTFICARE | S12: 45% CONS.INNOVA / 35% GETTEC / 20% SANTA TERESA | T12: CS NON SOSTIENE COSTO, RIBALTA SUBITO QUANTO RICEVUTO DA PROGTTISTA | U12: https://www.sintel.regione.lombardia.it/eprocdata/auctionDetail.xhtml?id=219510451 | W12: Sintel ID 219510451 — ASP Pavia — Procedura aperta | X12: da Sintel (login SPID)
A13: =HYPERLINK("F:\Appalti\ASP Pavia Lavori","Apri") -> Apri | B13: ASP PAVIA | C13: LAVORI | D13: 989218 | E13: 1 | F13: 1 | G13: 1 | H13: 1 | J13: SI | K13: 46204 | N13: / | O13: 1 | P13: MENS | Q13: NON SOSTENUTI DA CS | R13: DA QUANTFICARE | S13: 70% FERVO / 30% CS | U13: https://www.sintel.regione.lombardia.it/eprocdata/auctionDetail.xhtml?id=220127460 | W13: Sintel ID 220127460 — ASP Pavia — Procedura aperta | X13: da Sintel (login SPID)
A14: IN ELABORAZIONE (2 procedure)
A15: =HYPERLINK("F:\Appalti\Consip MIES 2950","Apri") -> Apri | B15: CONSIP MIES - ID 2950 | C15: AQ MULTISERVIZIO INTEGRATO ENERGIA SSN — ED. 2 | D15: 3289440000 | E15: 5 | F15: TBD | J15: da definire | K15: 30/09/2026 h. 16:00 | L15: 02/10/2026 h. 15:00 | M15: 02/10/2026 | N15: 36 mesi (AQ) + 6/9 anni (contratti) | O15: Accordo Quadro | P15: TBD | S15: ATI da definire | T15: 🔴 BANDO PUBBLICATO 28/08/2026. Determina 25/08/2026. Chiarimenti entro 11/09/2026. Piattaforma Acquistinretepa (Consip). Vincolo max 2 lotti (L1-L4). | U15: =HYPERLINK("https://www.acquistinretepa.it/","Acquistinretepa") -> Acquistinretepa | W15: Consip ID 2950 — Determina 25/08/2026 — Avviso preinformazione 28/05/2026 — RUP proget.: Ing. Simona Petetta — RUP procedim.: Dott. Claudio Antonini | X15: L1: BCC72E2B3A | L2: BCC72E3C0D | L3: BCC72E4CE0 | L4: BCC72E5DB3 | L5: BCC72E6E86
A16: =HYPERLINK("F:\Appalti\Multiservizio AASS Lazio Ed 4","Apri") -> Apri | B16: REGIONE LAZIO — DIREZIONE CENTRALE ACQUISTI | C16: MULTISERVIZIO TECNOLOGICO AASS LAZIO — ED. 4 (EPC) | D16: 2010788785 | E16: 10 | F16: TBD (max 1) | J16: OBBLIGATORIO (entro 30 gg da scadenza) | K16: 29/10/2026 (indicativa — verificare S.Tel.LA) | L16: da definire | M16: da definire | N16: Convenzione 24 mesi + Ordinativi 108 mesi + proroga 6 mesi | O16: Convenzione + Ordinativi | P16: TBD | S16: ATI GETEC 80% / CS 20% (da riconfermare per Ed. 4) | T16: 🔴 BANDO PUBBLICATO 12/06/2026. 10 lotti, MAX 1 lotto per operatore. Tecnica 70/Economica 30. RUP: Ing. Alessio Primavera. Sopralluogo obbligatorio. Base gara 1.601 mld €. | U16: =HYPERLINK("https://centraleacquisti.regione.lazio.it/","STEL.LA") -> STEL.LA | W16: Regione Lazio — Multiservizio AASS Ed. 4 — Disciplinare 12/06/2026 — Piattaforma S.Tel.LA — RUP Ing. Alessio Primavera (aprimavera@regione.lazio.it) | X16: CIG per singolo lotto — non pubblicati nel disciplinare schema (leggere su S.Tel.LA)
A17: FUTURE (3 procedure) | U17: https://www.sintel.regione.lombardia.it/eprocdata/sintelSearch.xhtml
A18: =HYPERLINK("F:\Appalti\Consip SIE PAC ED 1","Apri") -> Apri | B18: CONSIP | C18: SIE PAC ED. 1 | D18: ND | E18: ND | F18: ND | G18: ND | H18: ND | J18: ND | K18: ND | N18: ND | O18: ND | P18: ND | Q18: ND | R18: ND | S18: TBD | T18: TBD | U18: https://www.conferenzastatocitta.gov.it/home/notizie-e-comunicati/2026/servizio-integrato-energia-gara-consip-per-le-amministrazioni-locali/ | W18: Consip SIE PAC ed. 1 — Consultazione di mercato (questionario chiuso 19/01/2025) | X18: CIG attesi al bando
A19: =HYPERLINK("F:\Appalti\Azienda Zero","Apri") -> Apri | B19: AZIENDA ZERO | C19: SERVIZIO ENERGIA / EPC | E19: 5 | F19: 5 | G19: 1 | H19: 5 | J19: SI | K19: ND | N19: ND | O19: 3+2 | P19: MENS | Q19: ND | R19: ND | S19: GETEC 80% - CS 20% | T19: Info future | U19: https://www.sintel.regione.lombardia.it/eprocdata/sintelSearch.xhtml | W19: Numero gara 9436015 — Sintel ID 176837685 — Codice 2023.026 — Delibera DG 730/2023 | X19: CIG Lotto 6: A02D9A71A2 (vedi sentenza TAR Veneto 2498/2025 RG 1834/2025)
A20: =HYPERLINK("F:\Appalti\DAP Carceri","Apri") -> Apri | B20: DAP | C20: PPP CARCERI | D20: ND | E20: 9 | F20: 9 | G20: 9 | H20: ND | J20: SI | K20: ND | N20: ND | O20: 15/20 ANNI | P20: TBD | Q20: ND | R20: ND | S20: GETEC - CS oppure RENOVIT-DEVI-CS | T20: Ministero Giustizia/DAP — Manifestazione di interesse PPP Energia (scad. 31/12/2024) | U20: DAP - Avviso PPP Energia | W20: Avviso DAP 20/08/2024 (SBG1416417) — Linee guida DAP-Demanio 30/03/2025 pubblicate 03/04/2026 (SBG1498554) | X20: CIG attesi al bando
U21: https://www.giustizia.it/giustizia/page/it/scheda_di_sintesi_gare_o_contratti?contentId=SBG1416417

Sheet Dashboard
B2: DASHBOARD PROSPETTO ATTIVITÀ COMMERCIALE
B3: =CONCATENATE("Aggiornato al ",TEXT(TODAY(),"d mmmm yyyy")) -> Aggiornato al 10 September 2026
B5: TOTALI PER STATO
B6: Stato | C6: N° procedure | D6: Importo totale (€) | E6: Importo CS partecipato (€) | F6: % CS su totale
B7: PASSATE | C7: =COUNTIF('Prospetto A3'!$A$5:$A$5,"<>") -> 1 | D7: =SUM('Prospetto A3'!$D$5) -> 197075590 | E7: =SUM('Prospetto A3'!$I$5) -> 0 | F7: =IFERROR(E7/D7,0) -> 0
B8: IN VALUTAZIONE | C8: =COUNTA('Prospetto A3'!$B$7:$B$10) -> 4 | D8: =SUM('Prospetto A3'!$D$7:$D$10) -> 2.0676342e+09 | E8: =SUM('Prospetto A3'!$I$7:$I$10) -> 1080703034 | F8: =IFERROR(E8/D8,0) -> 0.52267611
B9: IN CORSO | C9: =COUNTA('Prospetto A3'!$B$12:$B$13) -> 2 | D9: =SUM('Prospetto A3'!$D$12:$D$13) -> 22654407 | E9: =SUM('Prospetto A3'!$I$12:$I$13) -> 0 | F9: =IFERROR(E9/D9,0) -> 0
A10: 🔴 | B10: IN ELABORAZIONE | C10: =COUNTA('Prospetto A3'!$B$15:$B$16) -> 2 | D10: =SUM('Prospetto A3'!$D$15:$D$16) -> 5300228785 | E10: =SUMIF('Prospetto A3'!$I$15:$I$16,">0") -> 0
B11: FUTURE | C11: =COUNTA('Prospetto A3'!$B$18:$B$20) -> 3 | D11: =SUMIF('Prospetto A3'!$D$18:$D$20,">0") -> 0 | E11: =SUMIF('Prospetto A3'!$I$18:$I$20,">0") -> 0 | F11: =IFERROR(E10/D10,0) -> 0
B12: TOTALE | C12: =SUM(C7:C10) -> 9 | D12: =SUM(D7:D10) -> 7.587593e+09 | E12: =SUM(E7:E10) -> 1080703034 | F12: =IFERROR(E11/D11,0) -> 0
B14: PROSSIME SCADENZE (offerte)
B15: Ente | C15: Descrizione | D15: Scadenza | E15: Giorni residui | F15: Stato
B16: ='Prospetto A3'!B5 -> STADIO SAN SIRO | C16: ='Prospetto A3'!C5 -> CONCESSIONE | D16: ='Prospetto A3'!K5 -> 0 | E16: =IF(ISNUMBER(D15),D15-TODAY(),"") | F16: =IF(NOT(ISNUMBER(D15)),"—",IF(E15<0,"Scaduta",IF(E15<=7,"URGENTE",IF(E15<=30,"Attenzione","Tranquilla")))) -> —
B17: ='Prospetto A3'!B7 -> COMUNE DI ALGHERO | C17: ='Prospetto A3'!C7 -> PPP TERMICO E PUBBLICA ILLUM | D17: ='Prospetto A3'!K7 -> 46136 | E17: =IF(ISNUMBER(D16),D16-TODAY(),"") | F17: =IF(NOT(ISNUMBER(D16)),"—",IF(E16<0,"Scaduta",IF(E16<=7,"URGENTE",IF(E16<=30,"Attenzione","Tranquilla")))) -> —
B18: ='Prospetto A3'!B8 -> ARIA | C18: ='Prospetto A3'!C8 -> MANUTENZIONE IMP. ELETTRICI SANITA' PR. AP. ART 71 | D18: ='Prospetto A3'!K8 -> 46160 | E18: =IF(ISNUMBER(D17),D17-TODAY(),"") -> -139 | F18: =IF(NOT(ISNUMBER(D17)),"—",IF(E17<0,"Scaduta",IF(E17<=7,"URGENTE",IF(E17<=30,"Attenzione","Tranquilla")))) -> Tranquilla
B19: ='Prospetto A3'!B9 -> ARIA | C19: ='Prospetto A3'!C9 -> MANUTEZIONE IMP.IDRICI PR. AP.ART71 | D19: ='Prospetto A3'!K9 -> 46168 | E19: =IF(ISNUMBER(D18),D18-TODAY(),"") -> -115 | F19: =IF(NOT(ISNUMBER(D18)),"—",IF(E18<0,"Scaduta",IF(E18<=7,"URGENTE",IF(E18<=30,"Attenzione","Tranquilla")))) -> Scaduta
B20: ='Prospetto A3'!B10 -> CONSIP | C20: ='Prospetto A3'!C10 -> AQ SERVIZIO INTEGRATO ENERGIA PAL | D20: ='Prospetto A3'!K10 -> 46147 | E20: =IF(ISNUMBER(D19),D19-TODAY(),"") -> -107 | F20: =IF(NOT(ISNUMBER(D19)),"—",IF(E19<0,"Scaduta",IF(E19<=7,"URGENTE",IF(E19<=30,"Attenzione","Tranquilla")))) -> Scaduta
B21: ='Prospetto A3'!B12 -> ASP PAVIA | C21: ='Prospetto A3'!C12 -> EPC | D21: ='Prospetto A3'!K12 -> 46195 | E21: =IF(ISNUMBER(D20),D20-TODAY(),"") -> -128 | F21: =IF(NOT(ISNUMBER(D20)),"—",IF(E20<0,"Scaduta",IF(E20<=7,"URGENTE",IF(E20<=30,"Attenzione","Tranquilla")))) -> Scaduta
B22: ='Prospetto A3'!B13 -> ASP PAVIA | C22: ='Prospetto A3'!C13 -> LAVORI | D22: ='Prospetto A3'!K13 -> 46204 | E22: =IF(ISNUMBER(D21),D21-TODAY(),"") -> -80 | F22: =IF(NOT(ISNUMBER(D21)),"—",IF(E21<0,"Scaduta",IF(E21<=7,"URGENTE",IF(E21<=30,"Attenzione","Tranquilla")))) -> Scaduta
B23: ='Prospetto A3'!B15 -> CONSIP MIES - ID 2950 | C23: ='Prospetto A3'!C15 -> AQ MULTISERVIZIO INTEGRATO ENERGIA SSN — ED. 2 | D23: ='Prospetto A3'!K15 -> 30/09/2026 h. 16:00 | E23: =IF(ISNUMBER(D22),D22-TODAY(),"") -> -71 | F23: =IF(NOT(ISNUMBER(D22)),"—",IF(E22<0,"Scaduta",IF(E22<=7,"URGENTE",IF(E22<=30,"Attenzione","Tranquilla")))) -> Scaduta
B24: ='Prospetto A3'!B16 -> REGIONE LAZIO — DIREZIONE CENTRALE ACQUISTI | C24: ='Prospetto A3'!C16 -> MULTISERVIZIO TECNOLOGICO AASS LAZIO — ED. 4 (EPC) | D24: ='Prospetto A3'!K16 -> 29/10/2026 (indicativa — verificare S.Tel.LA) | E24: =IF(ISNUMBER(D23),D23-TODAY(),"") | F24: =IF(NOT(ISNUMBER(D23)),"—",IF(E23<0,"Scaduta",IF(E23<=7,"URGENTE",IF(E23<=30,"Attenzione","Tranquilla")))) -> —
B25: ='Prospetto A3'!B18 -> CONSIP | C25: ='Prospetto A3'!C18 -> SIE PAC ED. 1 | D25: ='Prospetto A3'!K18 -> ND | E25: =IF(ISNUMBER(D24),D24-TODAY(),"") | F25: =IF(NOT(ISNUMBER(D24)),"—",IF(E24<0,"Scaduta",IF(E24<=7,"URGENTE",IF(E24<=30,"Attenzione","Tranquilla")))) -> —
B26: ='Prospetto A3'!B19 -> AZIENDA ZERO | C26: ='Prospetto A3'!C19 -> SERVIZIO ENERGIA / EPC | D26: ='Prospetto A3'!K19 -> ND | E26: =IF(ISNUMBER(D25),D25-TODAY(),"") | F26: =IF(NOT(ISNUMBER(D25)),"—",IF(E25<0,"Scaduta",IF(E25<=7,"URGENTE",IF(E25<=30,"Attenzione","Tranquilla")))) -> —
B27: ='Prospetto A3'!B20 -> DAP | C27: ='Prospetto A3'!C20 -> PPP CARCERI | D27: ='Prospetto A3'!K20 -> ND | E27: =IF(ISNUMBER(D26),D26-TODAY(),"") | F27: =IF(NOT(ISNUMBER(D26)),"—",IF(E26<0,"Scaduta",IF(E26<=7,"URGENTE",IF(E26<=30,"Attenzione","Tranquilla")))) -> —
B29: BREAKDOWN PER ENTE COMMITTENTE
B30: Ente | C30: N° gare | D30: Importo totale (€)
B31: ARIA | C31: =COUNTIF('Prospetto A3'!B5:B20,"ARIA") -> 2 | D31: =SUMIF('Prospetto A3'!B5:B20,"ARIA",'Prospetto A3'!D5:D20) -> 18712286
B32: CONSIP | C32: =COUNTIF('Prospetto A3'!B5:B20,"CONSIP") -> 2 | D32: =SUMIF('Prospetto A3'!B5:B20,"CONSIP",'Prospetto A3'!D5:D20) -> 2015086959
B33: ASP PAVIA | C33: =COUNTIF('Prospetto A3'!B5:B20,"ASP PAVIA") -> 2 | D33: =SUMIF('Prospetto A3'!B5:B20,"ASP PAVIA",'Prospetto A3'!D5:D20) -> 22654407
B34: AZIENDA ZERO | C34: =COUNTIF('Prospetto A3'!B5:B20,"AZIENDA ZERO") -> 1 | D34: =SUMIF('Prospetto A3'!B5:B20,"AZIENDA ZERO",'Prospetto A3'!D5:D20) -> 0
B35: REGIONE LAZIO | C35: =COUNTIF('Prospetto A3'!B5:B20,"REGIONE LAZIO") -> 0 | D35: =SUMIF('Prospetto A3'!B5:B20,"REGIONE LAZIO",'Prospetto A3'!D5:D20) -> 0
B36: COMUNE DI ALGHERO | C36: =COUNTIF('Prospetto A3'!B5:B20,"COMUNE DI ALGHERO") -> 1 | D36: =SUMIF('Prospetto A3'!B5:B20,"COMUNE DI ALGHERO",'Prospetto A3'!D5:D20) -> 33835000
B37: STADIO SAN SIRO | C37: =COUNTIF('Prospetto A3'!B5:B20,"STADIO SAN SIRO") -> 1 | D37: =SUMIF('Prospetto A3'!B5:B20,"STADIO SAN SIRO",'Prospetto A3'!D5:D20) -> 197075590
B38: CONSIP MIES - ID 2950 | C38: =COUNTIF('Prospetto A3'!B5:B20,"CONSIP MIES - ID 2950") -> 1 | D38: =SUMIF('Prospetto A3'!B5:B20,"CONSIP MIES - ID 2950",'Prospetto A3'!D5:D20) -> 3289440000
B39: DAP | C39: =COUNTIF('Prospetto A3'!B5:B20,"DAP") -> 1 | D39: =SUMIF('Prospetto A3'!B5:B20,"DAP",'Prospetto A3'!D5:D20) -> 0
B42: KPI RAPIDI
B43: Gare urgenti (scadenza ≤ 7gg) | C43: =COUNTIF(F15:F26,"URGENTE") -> 0
B44: Gare con scadenza in attenzione (8-30gg) | C44: =COUNTIF(F15:F26,"Attenzione") -> 0
B45: Gare con scadenza tranquilla (>30gg) | C45: =COUNTIF(F15:F26,"Tranquilla") -> 1
B46: Gare già scadute | C46: =COUNTIF(F15:F26,"Scaduta") -> 5
...

Sheet Stadio San Siro
A1: STADIO SAN SIRO — GFU "GRANDE FUNZIONE URBANA"
A2: Procedura ex art. 4 c.13 D.Lgs. 38/2021 ("Legge Stadi") — Compendio immobiliare comprensivo dello Stadio "Giuseppe Meazza"
A4: IDENTIFICAZIONE
A5: Stazione appaltante | B5: Comune di Milano
A6: Tipo procedura | B6: Avviso pubblico ex art. 4 c.13 D.Lgs. 38/2021 — Legge Stadi
A7: Acquirenti finali | B7: F.C. Internazionale Milano S.p.A. + A.C. Milan S.p.A.
A8: Veicolo societario | B8: Stadio San Siro S.p.A.
A9: Stato | B9: CONCLUSA — Rogito firmato 05/11/2025
A10: Oggetto | B10: Vendita del compendio immobiliare "Ambito GFU San Siro" comprensivo dello Stadio Meazza
A11: Superficie totale | B11: Circa 280.000 m² (stadio ~70.000 m² + aree edificabili limitrofe ~211.000 m²)
A12: Indice di edificabilità | B12: 0,35 mq/mq — Diritti edificatori: 98.321 mq SL
A14: VALORI ECONOMICI
A15: Prezzo di vendita | B15: 197075590
A16: Stima Agenzia delle Entrate | B16: 197075590
A17: Prima rata al rogito | B17: 73000000
A18: Quota rateizzata con fideiussioni | B18: 124075590
A19: Investimento complessivo Inter+Milan | B19: 1250800000
A20: - Nuovo stadio | B20: 707900000
A21: - Comparto plurivalente | B21: 390100000
A22: Quota Comune Milano (bonifiche, Patroclo) | B22: 22000000
A23: Contributo sostenibilità ambientale | B23: 14000000
A25: CRONOLOGIA
A26: 11/03/2025 | B26: Proposta congiunta Inter + Milan ex art. 4 c.13 D.Lgs. 38/2021
A27: 18/03/2025 | B27: DGC linee di indirizzo
A28: 24/03/2025 | B28: Avviso pubblico raccolta manifestazioni interesse (Det. Dir. n. 2213)
A29: 15/04/2025 | B29: Prima Conferenza dei Servizi preliminare
A30: 30/04/2025 | B30: Chiusura avviso — nessuna proposta migliorativa pervenuta
A31: 17/09/2025 | B31: Giunta favorevole agli elementi essenziali
A32: 29/09/2025 | B32: Delibera Consiglio Comunale (24 favorevoli / 20 contrari / 0 astenuti)
A33: 24/10/2025 | B33: DG n. 1321 approvazione schema Convenzione Quadro
A34: 05/11/2025 | B34: Firma rogito (Rep. n. 77207, Racc. n. 16709) e Convenzione Quadro
A35: 31/03/2026 | B35: Perquisizione GdF — indagine Procura Milano per turbativa d'asta
A37: STRALCI FUNZIONALI (Convenzione Quadro)
A38: Stralcio 1 — Stadio | B38: Nuovo impianto 70.000-71.500 spettatori + volumi chiusi funzionali
A39: Stralcio 2 — Plurivalente | B39: Restanti funzioni urbane + rifunzionalizzazione porzione Meazza conservata
A40: Verde pubblico | B40: ≥50% della superficie GFU + 80.000 mq di verde profondo
A41: Demolizione | B41: Demolizione ~91% del Meazza esistente; conservata porzione secondo anello (vincolo Soprintendenza dal 10/11/2025)
A43: SOGGETTI E FORNITORI
A44: Progettazione | B44: Foster + Partners (Lord Norman Foster) + MANICA (David Manica)
A45: Coordinatori finanziamento | B45: Goldman Sachs + JP Morgan
...

Sheet Comune di Alghero
A1: COMUNE DI ALGHERO — PPP TERMICO E PUBBLICA ILLUMINAZIONE
A2: Concessione in Partenariato Pubblico-Privato — Servizio Energia + Illuminazione Pubblica
A4: IDENTIFICAZIONE
A5: Stazione appaltante | B5: Comune di Alghero (SS)
A6: Stato | B6: NON ANCORA PUBBLICATO — In attesa di bando
A7: Oggetto | B7: PPP termico + pubblica illuminazione
A8: Tipo procedura | B8: Partenariato Pubblico Privato (art. 174 e ss D.Lgs. 36/2023)
A10: VALORI ECONOMICI E DURATA
A11: Valore stimato | B11: 33835000
A12: Durata | B12: 20 anni
A14: STRUTTURA LOTTI E SOPRALLUOGO
A15: Lotti | B15: 1
A16: Sopralluogo | B16: Sì (data prevista 24/04/2026)
A18: ATI PREVISTA — PARTECIPAZIONE CERTOSA
A19: Mandataria | B19: RENOVIT (55%)
A20: Mandante | B20: GETEC (45%)
A21: Quota CS | B21: 20% subappaltato passante per Certosa Servizi
A22: Progettista | B22: INGEIA — Costi progetto non sostenuti da CS
A24: NOTE OPERATIVE
A25: Nessuna procedura PPP termico/illuminazione attualmente aperta sul portale del Comune. Quando il bando sarà pubblicato sul portale appalti, caricare il PDF nella cartella F:\Appalti\Comune di Alghero\ per costruire il foglio di dettaglio completo.
A27: LINK UFFICIALI
A28: Portale appalti Alghero (Maggioli Cloud) | B28: https://alghero.maggiolicloud.it/portaleappalti/it/homepage.wp
A30: AZIONE
A31: Monitoraggio | B31: Registrarsi al portale Maggioli e attivare alert con parole chiave: "PPP", "illuminazione", "servizio energia"
A33: ⚠️ DISCREPANZA DA VERIFICARE (segnalata 19/06/2026)
A34: Fonte segnalazione | B34: QualEnergia.it PRO (testata energia/efficientamento)
A35: Contenuto avviso | B35: "Avviso pubblico per la presentazione di proposte di P.P.P. per la riqualificazione e gestione energetica di immobili di proprietà della pubblica amministrazione del comune di Alghero (SS)"
A36: Importo dichiarato | B36: n.d. (non disponibile sul portale)
A37: Scadenza segnalata | B37: 27/02/2026
A38: Scadenza nel prospetto | B38: 24/04/2026
A39: Ipotesi 1 | B39: Bando pre-pubblicato e poi ritirato (è già passata la scadenza 27/02)
A40: Ipotesi 2 | B40: Si tratta di una procedura diversa dal PPP termico+illuminazione tracciato
A41: Ipotesi 3 | B41: La scadenza nel prospetto è da aggiornare
A42: Link verifica | B42: https://www.qualenergia.it/pro/documenti/riqualificazione-energetica-immobili-di-proprieta-comune-di-alghero-ss/
A43: Azione | B43: Verificare con uffici Certosa Servizi quale dei due dati è corretto; controllare albo pretorio Alghero per qualsiasi procedura con scadenza 27/02/2026

Sheet ARIA 2026 401
A1: ARIA — MANUTENZIONE IMPIANTI ELETTRICI (ARIA_2026_401)
A2: Sintesi del Bando UE e del Disciplinare di gara — procedura aperta art. 71 D.Lgs. 36/2023
A4: IDENTIFICAZIONE
A5: Codice procedura | B5: ARIA_2026_401
A6: Stazione appaltante | B6: ARIA S.p.A. — Azienda Regionale per l'Innovazione e gli Acquisti (Regione Lombardia)
A7: Oggetto | B7: Servizio di manutenzione degli impianti elettrici in favore degli Enti del SIREG
A8: Beneficiari | B8: Enti del SIREG: Province, Fondazione IRCCS Policlinico, IZSLER, ARIA S.p.A. sede Catania
A9: CPV principale | B9: 50711000 — Servizi di riparazione e manutenzione di impianti elettrici di edifici
A10: Pubblicazione UE | B10: GU UE S 72/2026 del 14/04/2026 — avviso n. 254042-2026
A11: Identificativo UE | B11: 7ce359f9-5275-4912-bb73-25dfee2a4c03
A12: CCNL applicato | B12: Metalmeccanico — installazione impianti
A14: PROCEDURA, IMPORTI E DURATA
A15: Tipologia procedura | B15: Procedura aperta art. 71 D.Lgs. 36/2023 — inversione procedimentale (art. 107 c.3)
A16: Criterio di aggiudicazione | B16: Offerta economicamente più vantaggiosa (OEPV) — PT 70 / PE 30
A17: Importo a base d'asta (ribassabile) | B17: 12628155
A18: Oneri sicurezza interferenze (non ribassabili) | B18: 123412.87
A19: Opzione quinto d'obbligo (+20%, art. 120 c.9) | B19: 2550313.6
A20: Valore globale stimato dell'appalto | B20: 15301882
A21: Costi manodopera (stimati) | B21: 6278341.9
A22: Durata contratti di fornitura | B22: 36 mesi
A23: Validità dell'offerta | B23: 270 giorni dalla scadenza presentazione
A24: Garanzia provvisoria | B24: 2% del valore globale dei lotti di partecipazione
A25: Suddivisione | B25: 7 lotti — partecipabili e aggiudicabili tutti
A26: Subappalto | B26: Ammesso ai sensi dell'art. 119 D.Lgs. 36/2023
A27: Avvalimento | B27: Ammesso ai sensi dell'art. 104 D.Lgs. 36/2023
A28: Piattaforma di gara | B28: Sintel — www.ariaspa.it
A30: SCADENZE
A31: Termine richiesta chiarimenti | B31: 46153
A32: Scadenza presentazione offerte | B32: 46160
A33: Apertura pubblica delle offerte | B33: 46162
A35: SUDDIVISIONE IN LOTTI (€, IVA esclusa)
A36: Lotto | B36: Ente / Sede | C36: Importo contratto | D36: Opzione quinto (+20%) | E36: Valore globale lotto
A37: 1 | B37: Provincia di Milano | C37: =E37/1.2 -> 253438.05 | D37: =E37-C37 -> 50687.61 | E37: 304125.66
A38: 2 | B38: Provincia di Brescia | C38: =E38/1.2 -> 578120.1 | D38: =E38-C38 -> 115624.02 | E38: 693744.12
A39: 3 | B39: Fondazione IRCCS Cà Granda Ospedale Maggiore Policlinico | C39: =E39/1.2 -> 4001932.3 | D39: =E39-C39 -> 800386.46 | E39: 4802318.8
A40: 4 | B40: Provincia di Bergamo | C40: =E40/1.2 -> 4700550 | D40: =E40-C40 -> 940110 | E40: 5640660
A41: 5 | B41: Provincia di Pavia | C41: =E41/1.2 -> 389211.76 | D41: =E41-C41 -> 77842.352 | E41: 467054.11
A42: 6 | B42: I.Z.L.E.R. — Istituto Zooprofilattico Lombardia/E.Romagna | C42: =E42/1.2 -> 2666400 | D42: =E42-C42 -> 533280 | E42: 3199680
A43: 7 | B43: ARIA S.p.A. — sede di Catania | C43: =E43/1.2 -> 161916 | D43: =E43-C43 -> 32383.2 | E43: 194299.2
A44: Tot. | B44: Totale | C44: =SUM(C37:C43) -> 12751568 | D44: =SUM(D37:D43) -> 2550313.6 | E44: =SUM(E37:E43) -> 15301882
...

Sheet ARIA 2026 410
A1: ARIA — MANUTENZIONE IMPIANTI IDRICI (ARIA_2026_410)
A2: Sintesi del Bando UE e del Disciplinare di gara — procedura aperta art. 71 D.Lgs. 36/2023
A4: IDENTIFICAZIONE
A5: Codice procedura | B5: ARIA_2026_410
A6: Stazione appaltante | B6: ARIA S.p.A. — Azienda Regionale per l'Innovazione e gli Acquisti (Regione Lombardia)
A7: Oggetto | B7: Servizio di manutenzione degli impianti idrici in favore degli Enti del SIREG
A8: Beneficiari | B8: Enti del SIREG: Finlombarda, Policlinico, ATS Città Metr. Milano, ASST Bergamo Est/Ovest, ASST Spedali Civili Brescia, ATS Val Padana, ASST Lodi, ATS Pavia, IZSLER, ARIA S.p.A. sede Catania
A9: CPV principale | B9: 50711000-2 — Servizi di riparazione e manutenzione di impianti idrici
A10: Codice ATECO | B10: 43.22.01
A11: Pubblicazione UE | B11: Avviso n. 276431-2026
A12: CCNL applicato | B12: CNEL C011 Metalmeccanico Industria (lotti 2,3,5,6); CNEL C018 PMI industria metalmecc./installazione impianti (lotti 1,2,4)
A14: PROCEDURA, IMPORTI E DURATA
A15: Tipologia procedura | B15: Procedura aperta art. 71 D.Lgs. 36/2023 — inversione procedimentale (art. 107 c.3)
A16: Criterio di aggiudicazione | B16: Offerta economicamente più vantaggiosa (OEPV) — PT 70 / PE 30
A17: Importo a base d'asta (ribassabile) | B17: 5918949.5
A18: Oneri sicurezza interferenze (non ribassabili) | B18: 41767.91
A19: Opzione quinto d'obbligo (+20%, art. 120 c.9) | B19: 1192143.5
A20: Valore globale stimato dell'appalto | B20: 7152860.8
A21: Costi manodopera (stimati) | B21: 2334948.7
A22: Durata contratti di fornitura | B22: 36 mesi (variabile per ente: da 5 a 36 mesi)
A23: Validità dell'offerta | B23: 270 giorni dalla scadenza presentazione
A24: Garanzia provvisoria | B24: 2% del valore globale dei lotti di partecipazione
A25: Suddivisione | B25: 6 lotti — partecipabili e aggiudicabili tutti
A26: Subappalto | B26: Ammesso ai sensi dell'art. 119 D.Lgs. 36/2023
A27: Avvalimento | B27: Ammesso ai sensi dell'art. 104 D.Lgs. 36/2023
A28: Piattaforma di gara | B28: Sintel — www.ariaspa.it
A30: SCADENZE
A31: Termine richiesta chiarimenti | B31: 46161
A32: Scadenza presentazione offerte | B32: 46168
A33: Apertura pubblica delle offerte | B33: 46169
A34: N.B. — il Prospetto principale riporta apertura al 04/06/2026: verificare con la piattaforma Sintel se c'è stata proroga rispetto al bando UE (apertura ufficiale 27/05/2026).
A36: SUDDIVISIONE IN LOTTI (€, IVA esclusa)
A37: Lotto | B37: Ente principale / Provincia | C37: Importo contratto | D37: Opzione quinto (+20%) | E37: Valore globale lotto
A38: 1 | B38: Provincia MI — Finlombarda + Policlinico + ATS Città Metr. Milano | C38: =E38/1.2 -> 1491069.2 | D38: =E38-C38 -> 298213.83 | E38: 1789283
A39: 2 | B39: Provincia BG — ASST Bergamo Est + ASST Bergamo Ovest | C39: =E39/1.2 -> 3525968 | D39: =E39-C39 -> 705193.6 | E39: 4231161.6
A40: 3 | B40: Provincia BS — ASST Spedali Civili Brescia + ATS Val Padana | C40: =E40/1.2 -> 334011.66 | D40: =E40-C40 -> 66802.332 | E40: 400813.99
A41: 4 | B41: Province LO-PV — ASST Lodi + ATS Pavia | C41: =E41/1.2 -> 286089.8 | D41: =E41-C41 -> 57217.96 | E41: 343307.76
A42: 5 | B42: Lombardia/E.Romagna — IZSLER Bruno Ubertini | C42: =E42/1.2 -> 306913.75 | D42: =E42-C42 -> 61382.75 | E42: 368296.5
A43: 6 | B43: ARIA S.p.A. — sede di Catania | C43: =E43/1.2 -> 16665 | D43: =E43-C43 -> 3333 | E43: 19998
A44: Tot. | B44: Totale | C44: =SUM(C38:C43) -> 5960717.4 | D44: =SUM(D38:D43) -> 1192143.5 | E44: =SUM(E38:E43) -> 7152860.8
...

Sheet CONSIP ID 2849
A1: CONSIP — AQ SERVIZIO INTEGRATO ENERGIA PER LE PAL (ID 2849)
A2: Sintesi della Determina a contrarre (art. 17 D.Lgs. 36/2023) — v.1.9 del 12/11/2025 — doc. SGQ1_MODU_000234_00
A4: IDENTIFICAZIONE
A5: Codice identificativo | B5: ID 2849
A6: Stazione appaltante | B6: Consip S.p.A. (Ministero dell'Economia e delle Finanze)
A7: Oggetto | B7: Affidamento di un Accordo Quadro per il Servizio Integrato Energia per le Pubbliche Amministrazioni Locali
A8: Beneficiari | B8: Amministrazioni Locali del conto economico consolidato (L. 196/2009), escluse le Amministrazioni sanitarie
A9: Attività / ATECO | B9: Manut. riscaldamento e raffreddamento (43.22.0), impianti elettrici (43.21.01), erogazione gas (35.23) ed energia elettrica (35.15), progettazione impianti (71)
A10: CCNL applicato | B10: Metalmeccanico — installazione impianti (codice C011)
A12: PROCEDURA, IMPORTI E DURATA
A13: Tipologia procedura | B13: Procedura aperta — Accordo Quadro con più operatori (art. 59 c.4 lett. a D.Lgs. 36/2023; art. 2 c.225 L. 191/2009). Inversione procedimentale (art. 107 c.3).
A14: Criterio di aggiudicazione | B14: Offerta economicamente più vantaggiosa — miglior rapporto qualità/prezzo (art. 108). PT 70 / PE 30.
A15: Importo base stimato | B15: 1430000000 | C15: (IVA escl. — 80.000.000 m³)
A16: Importo globale con estensioni | B16: 2.015087e+09 | C16: (IVA esclusa)
A17: Durata Accordo Quadro | B17: 24 mesi + proroga fino a 12 mesi
A18: Durata contratti di fornitura | B18: 3 o 6 anni — estendibile di +2 anni (premiale, art. 120 c.10)
A19: Suddivisione | B19: 10 lotti geografici (aggregazione di regioni contigue con condizioni climatiche analoghe)
A21: RIPARTIZIONE DELL'IMPORTO TRA OPERATORI AGGIUDICATARI
A22: Offerte valide | B22: Aggiudicatari | C22: 1° | D22: 2° | E22: 3° | F22: Lotti
A23: N = 1 | B23: 1 | C23: 1 | D23: — | E23: — | F23: tutti
A24: N = 2 | B24: 2 | C24: 0.7 | D24: 0.3 | E24: — | F24: tutti
A25: N ≥ 3 | B25: 3 | C25: 0.55 | D25: 0.3 | E25: 0.15 | F25: 2, 3, 4, 7
A26: Nota: i lotti 1, 5, 6, 8, 9, 10 prevedono solo le ripartizioni N=1 (100%) e N≥2 (70/30%).
A28: SUDDIVISIONE IN LOTTI
A29: Lotto | B29: Aree territoriali | C29: Quantità max (m³) | D29: Importo stimato (€) | E29: Importo con estensioni (€)
A30: 1 | B30: Valle d'Aosta e Piemonte | C30: 7348000 | D30: 121000000 | E30: 1.7050736e+08
A31: 2 | B31: Lombardia e P.A. Bolzano | C31: 16019000 | D31: 201740000 | E31: 2.8428227e+08
A32: 3 | B32: Friuli-Venezia Giulia, Veneto e P.A. Trento | C32: 9590000 | D32: 188430000 | E32: 2.6552646e+08
A33: 4 | B33: Emilia-Romagna e Liguria | C33: 9566000 | D33: 154880000 | E33: 2.1824942e+08
A34: 5 | B34: Toscana e Umbria | C34: 6491000 | D34: 121990000 | E34: 1.7190242e+08
A35: 6 | B35: Marche e Abruzzo | C35: 5320000 | D35: 91740000 | E35: 1.2927558e+08
A36: 7 | B36: Lazio e Sardegna | C36: 7596000 | D36: 197780000 | E36: 2.7870203e+08
A37: 8 | B37: Campania e Molise | C37: 5672000 | D37: 109340000 | E37: 1.5407665e+08
A38: 9 | B38: Puglia e Basilicata | C38: 5434000 | D38: 99990000 | E38: 1.4090108e+08
A39: 10 | B39: Calabria e Sicilia | C39: 6964000 | D39: 143110000 | E39: 2.016637e+08
A40: Tot. | B40: Totale | C40: =SUM(C30:C39) -> 80000000 | D40: =SUM(D30:D39) -> 1430000000 | E40: =SUM(E30:E39) -> 2.015087e+09
A42: REQUISITI DI PARTECIPAZIONE PER LOTTO (€, IVA esclusa)
A43: Lotto | B43: Fatturato globale (3 su 5 anni) | C43: Serv. progettazione | D43: SOA OG11 — importo annuo lavori | E43: Classifica | F43: Esperienza pregressa (20%)
A44: 1 | B44: 18820000 | C44: 220000 | D44: 2201000 | E44: IV | F44: 1793000
A45: 2 | B45: 24660000 | C45: 288000 | D45: 2884000 | E45: IV | F45: 2989000
...

Sheet ASP Pavia EPC
A1: ASP PAVIA — ENERGY PERFORMANCE CONTRACT (EPC)
A2: Procedura aperta sulla Piattaforma Sintel — Regione Lombardia
A4: IDENTIFICAZIONE
A5: Stazione appaltante | B5: ASP Pavia — Azienda Servizi alla Persona
A6: Stato | B6: IN CORSO — Offerte da presentare entro 22/06/2026
A7: Oggetto | B7: Energy Performance Contract (EPC)
A8: ID Sintel | B8: 219510451
A10: VALORI E DURATA
A11: Importo | B11: 21665189
A12: Durata | B12: 12 anni
A13: Sopralluogo | B13: Sì
A14: Scadenza offerte | B14: 22/06/2026 (URGENTE — 4 giorni residui)
A16: STRUTTURA LOTTI
A17: Lotti | B17: 1
A18: Partecipanti | B18: 1
A19: Aggiudicabili | B19: 1
A21: ATI PREVISTA — PARTECIPAZIONE CERTOSA
A22: Mandataria | B22: Consorzio Innova (45%)
A23: Mandante 1 | B23: GETEC (35%)
A24: Mandante 2 | B24: Santa Teresa (20%)
A25: Progettista | B25: MENS — Costo progetto: 35.500 €
A26: Note | B26: CS non sostiene costo progetto: ribalta subito quanto ricevuto dal progettista
A28: DOCUMENTI
A29: Documentazione completa scaricabile da Sintel previa autenticazione SPID/CIE/CNS. Quando scarichi i PDF, caricarli in F:\Appalti\ASP Pavia EPC\.
A31: LINK UFFICIALI
A32: Dettaglio gara Sintel | B32: https://www.sintel.regione.lombardia.it/eprocdata/auctionDetail.xhtml?id=219510451
A33: Portale ARIA SpA | B33: https://www.ariaspa.it/

Sheet ASP Pavia Lavori
A1: ASP PAVIA — LAVORI CONNESSI ALL'EPC
A2: Procedura aperta sulla Piattaforma Sintel — Regione Lombardia
A4: IDENTIFICAZIONE
A5: Stazione appaltante | B5: ASP Pavia
A6: Stato | B6: IN CORSO — Offerte da presentare entro 01/07/2026
A7: Oggetto | B7: Lavori connessi all'EPC ASP Pavia
A8: ID Sintel | B8: 220127460
A10: VALORI E DURATA
A11: Importo | B11: 989218
A12: Durata | B12: 1 mese
A13: Sopralluogo | B13: Sì
A14: Scadenza offerte | B14: 01/07/2026 (13 giorni residui — Attenzione)
A16: ATI PREVISTA — PARTECIPAZIONE CERTOSA
A17: Mandataria | B17: FERVO (70%)
A18: Mandante | B18: Certosa Servizi (30%)
A19: Progettista | B19: MENS — Costi non sostenuti da CS
A21: DOCUMENTI
A22: Documentazione completa su Sintel (login SPID). Quando scarichi i PDF, caricarli in F:\Appalti\ASP Pavia Lavori\.
A24: LINK UFFICIALI
A25: Dettaglio gara Sintel | B25: https://www.sintel.regione.lombardia.it/eprocdata/auctionDetail.xhtml?id=220127460

Sheet Consip SIE PAC ED 1
A1: CONSIP — SIE PAC ED. 1
A2: Servizio Integrato Energia per le Pubbliche Amministrazioni Centrali — Consultazione di mercato in preparazione bando
A4: IDENTIFICAZIONE
A5: Stazione appaltante | B5: Consip S.p.A.
A6: Stato | B6: CONSULTAZIONE DI MERCATO — Questionario chiuso 19/01/2025; bando in fase di preparazione
A7: Beneficiari | B7: Pubbliche Amministrazioni Centrali (PAC)
A8: Edizione | B8: 1ª
A10: VALORI E STRUTTURA
A11: Importo stimato | B11: ND (bando ancora in preparazione)
A12: Lotti previsti | B12: ND
A14: STATO PROCEDURA
A15: Il questionario di consultazione di mercato è stato chiuso il 19/01/2025. Il bando di gara è in fase di preparazione presso Consip e potrebbe seguire una struttura simile a quella della SIE PAL (ID 2849), già bandita per le Amministrazioni Locali nel marzo 2026.
A17: LINK UFFICIALI
A18: Comunicato Conferenza Stato-Città | B18: https://www.conferenzastatocitta.gov.it/home/notizie-e-comunicati/2026/servizio-integrato-energia-gara-consip-per-le-amministrazioni-locali/
A19: Portale Consip | B19: https://www.consip.it/
A20: Portale Acquistinretepa | B20: https://www.acquistinretepa.it/
A22: AZIONE
A23: Monitoraggio | B23: Registrarsi su acquistinretepa.it e impostare alert su "SIE PAC" e "Servizio Integrato Energia".

Sheet Azienda Zero
A1: AZIENDA ZERO — GVE (Gestione Vettori Energetici)
A2: Procedura aperta telematica per le Aziende Sanitarie della Regione del Veneto — CRAV
A4: IDENTIFICAZIONE
A5: Stazione appaltante | B5: Azienda Zero — Centrale Acquisti Regione Veneto (CRAV)
A6: Stato | B6: AGGIUDICATA — Con ricorsi pendenti al TAR
A7: Oggetto | B7: Gestione dei Vettori Energetici delle Aziende Sanitarie della Regione del Veneto
A8: Procedura | B8: Aperta telematica — Convenzione Quadro ex art. 26 L. 488/1999
A9: Numero gara | B9: 9436015
A10: ID Sintel | B10: 176837685
A11: Codice Gara | B11: 2023.026
A12: Pubblicazione GURI | B12: V Serie Speciale n. 145 del 18/12/2023 + n. 38 del 29/03/2024
A14: STORIA DELLA PROCEDURA
A15: Gara originaria GETIS | B15: ANNULLATA dal Consiglio di Stato (Ottobre 2024)
A16: Sostituita da GVE | B16: Indetta con Delibera D.G. n. 730 del 28/11/2023
A17: Modifiche | B17: Delibere n. 104 del 01/03/2024 e n. 299/2024
A19: STRUTTURA E CRITERI
A20: Lotti | B20: 6
A21: Beneficiari | B21: Aziende Sanitarie del Veneto
A22: Criterio | B22: OEPV con soglia di sbarramento tecnica (min 40/70 pt)
A23: Vincolo | B23: Aggiudicazione a un solo lotto per concorrente (a scelta del 1° classificato)
A25: ESITO E RICORSI
A26: Partecipanti | B26: 17 concorrenti, tutti ammessi
A27: Esclusi | B27: 9 (mancato superamento soglia tecnica)
A28: Lotto 6 (ULSS 9 Scaligera) - CIG A02D9A71A2 | B28: Aggiudicato a Teckal — Gemmo 2ª — Ricorso TAR Veneto RG 1834/2025 (esito pendente)
A30: ATI PREVISTA — PARTECIPAZIONE CERTOSA
A31: Mandataria | B31: GETEC (80%)
A32: Mandante | B32: Certosa Servizi (20%)
A34: LINK UFFICIALI
A35: Bandi Azienda Zero | B35: https://www.azero.veneto.it/bandi-di-gara-fornitori
A36: BUR Veneto (delibere) | B36: https://bur.regione.veneto.it/
A37: Sentenza TAR Veneto | B37: https://mdp.giustizia-amministrativa.it/
A38: Chiarimenti GVE | B38: https://www.azero.veneto.it/documents/20126/9b74bc50-0a53-d87e-e9ca-f2be37252769
A40: DOCUMENTI
A41: Documentazione completa su Sintel ID 176837685 (login SPID/CNS). Quando scarichi i PDF, caricarli in F:\Appalti\Azienda Zero\.

Sheet Sanità Lazio
A1: SANITÀ LAZIO — SERVIZIO ENERGIA / EPC
A2: Centrale Acquisti Regione Lazio — Piano Biennale 2026-2027 (in programmazione)
A4: IDENTIFICAZIONE
A5: Stazione appaltante | B5: Centrale Acquisti Regione Lazio
A6: Stato | B6: PROGRAMMAZIONE — Bando non ancora pubblicato
A7: Oggetto | B7: Servizio Energia / Energy Performance Contract per il SSR Lazio
A8: Piano | B8: Piano Biennale 2026-2027 — Approvato con DGR n. 1314 del 30/12/2025
A10: STRUTTURA PREVISTA
A11: Lotti previsti | B11: 10
A12: Importo | B12: ND (bando non ancora pubblicato)
A13: Beneficiari | B13: Aziende sanitarie del SSR Lazio
A15: ATI PREVISTA — PARTECIPAZIONE CERTOSA
A16: Mandataria | B16: GETEC (80%)
A17: Mandante | B17: Certosa Servizi (20%)
A19: STATO PROCEDURA
A20: La gara è inclusa nel Piano Biennale 2026-2027 della Centrale Acquisti Regione Lazio, approvato con DGR n. 1314 del 30/12/2025. Bando atteso nel piano triennale. La piattaforma utilizzata sarà STEL.LA.
A22: LINK UFFICIALI
A23: Centrale Acquisti Lazio | B23: https://centraleacquisti.regione.lazio.it/
A24: Bandi in scadenza STEL.LA | B24: https://centraleacquisti.regione.lazio.it/bandi-e-strumenti-di-acquisto/bandi-di-gara-in-scadenza
A25: Sito Regione Lazio | B25: https://www.regione.lazio.it/
A27: AZIONE
A28: Monitoraggio | B28: Registrarsi sulla piattaforma STEL.LA con parole chiave: "servizio energia", "EPC", "sanità", "efficientamento".
A30: ⚠️ NOTA IMPORTANTE (aggiornamento 10/09/2026)
A31: Bando pubblicato | B31: La gara "Multiservizio Tecnologico AASS Regione Lazio Ed. 4" è stata pubblicata il 12/06/2026 sulla piattaforma S.Tel.LA. Si tratta della gara specifica precedentemente tracciata genericamente in questa scheda.
A32: Foglio dedicato | B32: Vedi foglio "Multiservizio Lazio Ed4" per tutti i dettagli operativi.
A33: Riferimento prospetto | B33: Nel Prospetto A3 la gara è ora in sezione "IN ELABORAZIONE" (riga 16).
A34: Scadenza indicativa | B34: 29/10/2026 (DA CONFERMARE su S.Tel.LA)
A35: Questa scheda | B35: Rimane come traccia storica della programmazione Sanità Lazio pre-pubblicazione bando (DGR 1163/2024).

Sheet DAP Carceri
A1: DAP — PPP ENERGIA CARCERI
A2: Ministero della Giustizia — Dipartimento Amministrazione Penitenziaria
A4: IDENTIFICAZIONE
A5: Stazione appaltante | B5: Ministero della Giustizia — DAP
A6: Ufficio | B6: Direzione Generale per la gestione dei beni, dei servizi e degli interventi in materia di edilizia penitenziaria — Ufficio III
A7: Stato | B7: 🆕 LINEE GUIDA PUBBLICATE 03/04/2026 — Bando di gara atteso
A8: Oggetto | B8: Sistema integrato di fornitura e gestione dell'energia + interventi di efficientamento energetico
A9: Procedura | B9: Partenariato Pubblico Privato (art. 174 e ss D.Lgs. 36/2023)
A10: Direttore Generale | B10: Antonio Bianco
A12: OBIETTIVI DELL'AVVISO
A13: Servizio Energia; ammodernamento impianti; riqualificazione energetica (solare termico/FV, cogenerazione); servizi di gestione; manutenzione ordinaria e straordinaria.
A15: PERIMETRO
A16: Istituti penitenziari coinvolti | B16: 178
A17: Provveditorati interregionali | B17: 16
A18: Durata stimata | B18: 15-20 anni
A20: CRONOLOGIA
A21: 20/08/2024 | B21: Pubblicazione Avviso pubblico manifestazione interesse
A22: 29/08/2024 | B22: Errata corrige indirizzi email PEC
A23: 29/11/2024 | B23: Pubblicazione risposte ai quesiti
A24: 09/12/2024 | B24: Pubblicazione aggiornamento risposte ai quesiti
A25: 31/12/2024 | B25: SCADENZA presentazione manifestazioni di interesse
A26: 20/05/2025 | B26: Pubblicazione elenco 43 operatori che hanno aderito
A28: OPERATORI ECONOMICI INTERESSATI (estratto)
A29: Tra i 43 operatori che hanno presentato manifestazione di interesse: A2A Calore & Servizi (Brescia), Comat (Torino), Devi Impianti (Busto Arsizio), Edison Next Government (Milano), Engie Servizi (Roma), GETEC Italia (Gragnano Trebbiense), Renovit Public Solutions (Milano), Siram (Milano), City Green Light (Vicenza), Geoside (Casalecchio di Reno), Gemmo (Arcugnano) e altri 32 operatori.
A31: ATI PREVISTA — PARTECIPAZIONE CERTOSA
A32: Opzione A | B32: GETEC + Certosa Servizi
A33: Opzione B | B33: RENOVIT + DEVI + Certosa Servizi
A35: STATO ATTUALE
A36: Accordo ex art. 15 L. 241/90 sottoscritto tra DAP e Agenzia del Demanio per la definizione di criteri specifici. La gara vera e propria sarà bandita dopo l'emanazione delle linee guida congiunte. Gli operatori interessati saranno informati con apposito avviso sul sito del Ministero.
A38: CONTATTI
A39: PEC presentazioni | B39: prot.dgbs.dap@giustiziacert.it
A40: Email informazioni | B40: gestioneimmobili.dgbs.dap@giustizia.it
A42: LINK UFFICIALI
A43: Pagina avviso DAP | B43: https://www.giustizia.it/giustizia/page/it/scheda_di_sintesi_gare_o_contratti?contentId=SBG1416417
A44: Risposte quesiti (9/12/2024) | B44: https://www.giustizia.it/cmsresources/cms/documents/dap_roma_manifestazione_energia_9dic2024_risposte_quesiti_aggiornamento.pdf
A45: Risposte quesiti (29/11/2024) | B45: https://www.giustizia.it/cmsresources/cms/documents/dap_roma_manifestazione_energia_13ago2024_risposte_quesiti.pdf
A46: Ministero Giustizia | B46: https://www.giustizia.it/
A48: 🆕 AGGIORNAMENTO 03/04/2026 — LINEE GUIDA PUBBLICATE
A49: Documento | B49: Linee di indirizzo 30 marzo 2025 — Partenariato Pubblico Privato per la realizzazione di un sistema integrato di fornitura e gestione dell'energia e interventi di efficientamento energetico per gli istituti penitenziari
A50: Firmatario | B50: Massimo Parisi — Vice capo del DAP e Direttore Generale reggente
...

Sheet Ricerca Gare
A1: RICERCA GARE — MONITORAGGIO AUTOMATICO DI BANDI E IDENTIFICATIVI
A2: Strumenti per sapere automaticamente quando una gara viene pubblicata e ottenere subito CIG, ID e documentazione.
A4: OBIETTIVO
A5: Per le gare in fase preliminare (consultazione di mercato, manifestazione di interesse, programmazione) il CIG ANAC non esiste ancora — viene attribuito solo all'atto della pubblicazione del bando. Servono quindi strumenti che monitorino i portali ufficiali e ci avvisino automaticamente quando una gara di interesse viene pubblicata, in modo da poter scaricare subito documentazione, CIG e identificativo.
A7: PORTALI UFFICIALI DA MONITORARE
A8: Portale | B8: A cosa serve | C8: Costo | D8: Notifiche email | E8: Note
A9: ANAC | B9: Banca dati ufficiale dei CIG (tutte le gare italiane) | C9: Gratis | D9: Sì (BDNCP) | E9: Fonte primaria: ogni CIG d'Italia passa di qui
A10: TED (UE) | B10: Gazzetta Ufficiale Europea — gare sopra soglia UE | C10: Gratis | D10: Sì (TED eSender) | E10: Per ARIA, CONSIP e gare grandi della PA
A11: Acquistinretepa.it | B11: Portale CONSIP — gare nazionali | C11: Gratis (registrazione) | D11: Sì | E11: Copre tutte le gare CONSIP (es. SIE PAC, MIES)
A12: Sintel — ARIA SpA | B12: Piattaforma Regione Lombardia | C12: Gratis (registrazione) | D12: Sì | E12: ARIA, ASP Pavia, Azienda Zero usano tutti Sintel
A13: STEL.LA | B13: Piattaforma Centrale Acquisti Regione Lazio | C13: Gratis (registrazione) | D13: Sì | E13: Copre le gare della sanità del Lazio
A14: Maggioli Cloud Alghero | B14: Portale appalti del Comune di Alghero | C14: Gratis | D14: Verificare | E14: Necessario per la gara PPP termico/illuminazione
A15: Giustizia.it / DAP | B15: Avvisi del Ministero della Giustizia | C15: Gratis | D15: Da verificare | E15: Per le procedure PPP delle carceri
A17: TRE STRADE POSSIBILI
A18: 1) AVVISI E-MAIL GRATUITI DAI PORTALI — la via più semplice
A19: Ci si registra una volta sola su ciascun portale (ANAC, TED, CONSIP, Sintel, STEL.LA...) e si impostano parole chiave (es. "manutenzione impianti elettrici", "servizio energia", "PPP illuminazione"). Quando viene pubblicato qualcosa di pertinente, arriva un'e-mail di avviso. PRO: gratis, nessuna installazione. CONTRO: si ricevono molte e-mail da fonti diverse, va filtrato manualmente.
A20: 2) AGGREGATORE COMMERCIALE — la via comoda a pagamento
A21: Servizi privati che monitorano automaticamente tutti i portali italiani e inviano un unico digest giornaliero o settimanale. Esempi: TelemacoBandi, BandiOnline, Appalti.net, InfoPlus Procurement. Costo indicativo: 80–250 €/mese. PRO: un'unica interfaccia, filtri precisi (CPV, importo, area geografica). CONTRO: ha un costo mensile e per gare locali o in fase pre-bando la copertura può non essere completa.
A22: 3) PROGRAMMA PERSONALIZZATO — la via più potente
A23: Piccolo programma in Python che ogni mattina (o quando lo si avvia con doppio clic) interroga le API pubbliche di ANAC e TED, legge i feed RSS dei portali (CONSIP, Sintel, STEL.LA), filtra le parole chiave di interesse e AGGIORNA DIRETTAMENTE QUESTO FILE EXCEL compilando le colonne CIG e ID GARA quando trova un bando nuovo. PRO: gratis dopo lo sviluppo, fa esattamente ciò che serve, si integra con il prospetto. CONTRO: va sviluppato (può farlo Claude in un'altra sessione di lavoro).
A25: CONFRONTO TRA LE TRE STRADE
A26: Aspetto | B26: 1) Avvisi e-mail | C26: 2) Aggregatore | D26: 3) Programma | E26: Vincitore
A27: Costo iniziale | B27: Gratis | C27: Gratis | D27: Sviluppo una tantum | E27: 1 e 2
A28: Costo mensile | B28: Gratis | C28: 80–250 €/mese | D28: Gratis | E28: 1 e 3
A29: Difficoltà iniziale | B29: Bassa (mezz'ora) | C29: Bassissima | D29: Media | E29: 2
A30: Manutenzione richiesta | B30: Quasi zero | C30: Zero | D30: Zero (versione manuale) | E30: 2 e 3
A31: Tutto in un'unica vista | B31: No (più e-mail) | C31: Sì | D31: Sì (nell'Excel) | E31: 2 e 3
A32: Copertura gare locali | B32: Sì, se iscritto | C32: Parziale | D32: Buona | E32: 1 e 3
A33: Aggiorna l'Excel solo | B33: No | C33: No | D33: SÌ | E33: 3
A34: Filtri per parole chiave | B34: Sì (per portale) | C34: Sì (centralizzati) | D34: Sì (totali) | E34: 2 e 3
A36: RACCOMANDAZIONE — PERCORSO CONSIGLIATO
A37: Approccio consigliato: COMBINARE la Strada 1 (subito, gratis) con la Strada 3 versione "manuale" (a breve, una tantum). I tre portali chiave da monitorare oggi sono ARIA/Sintel, CONSIP e ANAC: da soli coprono il 70% delle gare in lista. La Strada 3 viene poi sviluppata in un secondo momento come piccola app da aprire con un doppio clic, che aggiorna l'Excel da sola.
A38: FASE 1 — OGGI (gratis, 30 minuti di iscrizioni)
A39: Passo | B39: Cosa fare | C39: Tempo | D39: Costo | E39: Link / Riferimento
A40: 1 | B40: Registrarsi su ANAC (Servizi BDNCP) e attivare le notifiche sui nuovi CIG | C40: 10 min | D40: Gratis | E40: anticorruzione.it
A41: 2 | B41: Registrarsi su acquistinretepa.it (CONSIP) e impostare gli alert su SIE PAC e MIES | C41: 10 min | D41: Gratis | E41: acquistinretepa.it
A42: 3 | B42: Registrarsi su Sintel ARIA SpA con parole chiave per ARIA, ASP Pavia, Azienda Zero | C42: 10 min | D42: Gratis | E42: ariaspa.it
A43: 4 | B43: Iscriversi alla newsletter TED per gare sopra soglia UE | C43: 5 min | D43: Gratis | E43: ted.europa.eu
A45: FASE 2 — A BREVE (programma personalizzato)
A46: Passo | B46: Cosa fare | C46: Tempo | D46: Chi | E46: Note
...

Sheet Link Bandi
A1: LINK E DOCUMENTI DELLE GARE — RACCOLTA URL UFFICIALI
A2: Per ogni gara: stato attuale, link al portale ufficiale, link a documenti specifici quando reperibili. Aggiornato a giugno 2026.
A4: LEGENDA DEGLI STATI
B5: Bando attivo / documentazione disponibile
B6: In consultazione di mercato, manifestazione di interesse o programmazione
B7: Procedura chiusa o conclusa
A9: 🔴 GARE IN ELABORAZIONE — BANDI PUBBLICATI CON OFFERTE DA PRESENTARE
A10: Riga | B10: Ente | C10: Gara | D10: Stato | E10: Link diretto / Foglio riferimento | F10: Scadenza offerte
A11: 15 | B11: CONSIP | C11: MIES ID 2950 — Multiservizio Integrato Energia SSN (Ed. 2) | D11: 🔴 IN ELABORAZIONE | E11: Foglio "Consip MIES 2950" + Acquistinretepa.it (Piattaforma PAD) | F11: 30/09/2026 h.16:00
A12: 16 | B12: REGIONE LAZIO | C12: Multiservizio Tecnologico AASS Regione Lazio — Ed. 4 | D12: 🔴 IN ELABORAZIONE | E12: Foglio "Multiservizio Lazio Ed4" + centraleacquisti.regione.lazio.it (S.Tel.LA) | F12: 29/10/2026 (indic.)
A14: GARE CON DOCUMENTAZIONE GIÀ CARICATA NEL PROGETTO (vedere fogli di dettaglio)
A15: Riga
A16: 8 | B16: ARIA | C16: Manutenzione Impianti Elettrici | D16: Attivo | E16: Foglio "ARIA_2026_401" — Manutenzione Imp. Elettrici Sanità (RUP C. Schweigl) | F16: Scadenza offerte: 18/05/2026 ore 11:00
A17: 9 | B17: ARIA | C17: Manutenzione Impianti Idrici | D17: Attivo | E17: Foglio "ARIA_2026_410" — Manutenzione Imp. Idrici Sanità (GUUE 276431-2026) | F17: Scadenza offerte: 26/05/2026 ore 11:00
A18: 10 | B18: CONSIP | C18: AQ Servizio Integrato Energia PAL (ID 2849) | D18: Attivo | E18: Foglio "Consip ID 2849" — AQ SIE PAL (GUUE S 051 del 13/03/2026) | F18: Bando GU UE n. 176703-2026 del 13/03/2026
E19: https://www.consip.it/notizie-avvisi/pubblicata-la-consultazione-del-mercato-per-laffidamento-del-servizio-integrato-energia-per-le-pubbliche-amministrazioni-centrali-sie-pac
A20: GARE PER LE QUALI HO TROVATO LINK / DOCUMENTI ONLINE | E20: https://www.azero.veneto.it/bandi-di-gara-fornitori
A21: Riga | B21: Ente | C21: Gara | D21: Stato | E21: Link diretto | F21: Note
A22: 15 | B22: CONSIP | C22: MIES ID 2950 — Multiservizio Integrato Energia Sanità (Ed. 2) | D22: 🔴 IN ELABORAZIONE | E22: Consip ID 2950 — AQ MIES Ed. 2 (bando pubblicato 28/08/2026, offerte 30/09/2026 h.16) | F22: 🔴 BANDO PUBBLICATO. Determina 25/08/2026, offerte 30/09/2026 h.16, prima seduta 02/10/2026 h.15 (inversione procedimentale). CIG: L1 BCC72E2B3A / L2 BCC72E3C0D / L3 BCC72E4CE0 / L4 BCC72E5DB3 / L5 BCC72E6E86. Vincolo max 2 lotti L1-L4.
A23: 15 | B23: CONSIP | C23: MIES ID 2635 (ed. 1) - PRECEDENTE EDIZIONE già bandita | D23: Attivo | E23: Consip ID 2635 — AQ MIES ed. 1 (PRECEDENTE — riferimento) | F23: La nuova MIES (ID 2950) avrà struttura simile. Utile come riferimento.
A24: 18 | B24: CONSIP | C24: SIE PAC ED.1 - Servizio Integrato Energia Pubblica Amministrazione Centrale | D24: Consultazione | E24: Consip — Consultazione SIE PAC ed. 1 (questionario chiuso 19/01/2025) | F24: Questionario di mercato chiuso il 19/01/2025. Bando in fase di preparazione.
A25: 19
A26: 16 | B26: REGIONE LAZIO | C26: Multiservizio Tecnologico AASS Regione Lazio — Ed. 4 (EPC) | D26: 🔴 IN ELABORAZIONE | E26: Regione Lazio — Multiservizio AASS Ed. 4 (disciplinare 12/06/2026, offerte indic. 29/10/2026) | F26: 🔴 BANDO PUBBLICATO. Disciplinare 12/06/2026, offerte indicative 29/10/2026 (da confermare S.Tel.LA). 10 lotti - MAX 1 per operatore. RUP Ing. Alessio Primavera. Base gara 1.601 mld €. Vedi foglio "Multiservizio Lazio Ed4".
A27: 5 | B27: COMUNE DI MILANO | C27: PPP "San Siro" - GFU Compendio immobiliare | D27: Conclusa | E27: Comune Milano — Avviso DD 2213 del 24/03/2025 (S.Siro: rogito 05/11/2025) | F27: Avviso pubblico DLgs 38/2021 art.4 c.13 (24/03 - 30/04/2025). Rogito firmato 05/11/2025 a favore di Inter+Milan.
A28: 20 | B28: DAP - MIN. GIUSTIZIA | C28: PPP Sistema integrato energia istituti penitenziari | D28: Manif. interesse | E28: Giustizia.it — Avviso PPP Energia DAP (SBG1416417 + Linee guida 30/03/2025) | F28: Avviso manifestazione interesse scaduto 31/12/2024. 🆕 LINEE GUIDA pubblicate 03/04/2026 (vedi foglio "DAP Carceri"). Bando atteso.
A30: GARE CON LINK SINTEL GIÀ NEL PROSPETTO PRINCIPALE
A31: Riga | B31: Ente | C31: Gara | D31: Stato | E31: Link diretto | F31: Note
A32: 12 | B32: ASP PAVIA | C32: EPC - Energy Performance Contract | D32: Attivo / da verificare | E32: Sintel ID 219510451 — ASP Pavia EPC (procedura aperta, scad. 22/06/2026) | F32: ID procedura Sintel già nel Prospetto colonna U (riga 12).
A33: 13 | B33: ASP PAVIA | C33: Lavori connessi all'EPC | D33: Attivo / da verificare | E33: Sintel ID 220127460 — ASP Pavia Lavori (procedura aperta, scad. 01/07/2026) | F33: ID procedura Sintel già nel Prospetto colonna U (riga 13).
A35: GARE PER LE QUALI NON È DISPONIBILE DOCUMENTAZIONE ONLINE
A36: Riga | B36: Ente | C36: Gara | D36: Stato | E36: Portale di riferimento | F36: Note
A37: 7 | B37: COMUNE ALGHERO | C37: PPP termico e pubblica illuminazione | D37: Non pubblicato | E37: Portale Alghero (Maggioli) — ⚠️ anomalia scadenza QualEnergia 27/02/2026 | F37: Anomalia: QualEnergia.it PRO segnala avviso PPP con scadenza 27/02/2026 (importo n.d.); prospetto riporta 24/04/2026. Tre ipotesi: pre-pubblicazione ritirata / procedure diverse / prospetto da aggiornare. Verificare in azienda.
A39: NOTA OPERATIVA
A40: I link in questo foglio sono cliccabili: premi CTRL+clic sulla cella verde (link) per aprire la pagina nel browser. Per le gare in stato "Consultazione" o "Programmazione", l'apertura del bando ufficiale è prevista nei prossimi mesi: una volta uscito il bando, basterà caricare il PDF nel progetto Claude per generare un foglio di dettaglio analogo a quelli già creati (CONSIP ID 2849, ARIA 2026 401, ARIA 2026 410). Per il monitoraggio automatico, vedi il foglio "Ricerca Gare".

Sheet Consip MIES 2950
A1: CONSIP MIES 2950 — AQ MULTISERVIZIO INTEGRATO ENERGIA SSN (Ed. 2)
A3: Aggiornamento scheda | B3: 10 settembre 2026 — bando pubblicato
A4: Stato | B4: 🔴 BANDO PUBBLICATO — offerte 30/09/2026
A6: IDENTIFICAZIONE
A7: Ente aggiudicatore | B7: Consip S.p.A. per conto Ministero Economia e Finanze (MEF)
A8: Denominazione gara | B8: Procedura aperta per Accordo Quadro Multiservizio Integrato Energia per gli enti del Servizio Sanitario Nazionale — ID 2950 (Ed. 2)
A9: Determina a contrarre | B9: 25/08/2026
A10: Avviso preinformazione | B10: 28/05/2026 (2 avvisi)
A11: Pubblicazione bando | B11: 28/08/2026
A12: Consultazione mercato precedente | B12: chiusa 19/12/2025
A13: Convenzione precedente | B13: MIES ID 1379 (Ed. 1) in scadenza
A14: RUP progetto | B14: Ing. Simona Petetta
A15: RUP procedimento affidam. | B15: Dott. Claudio Antonini
A16: Piattaforma | B16: PAD Acquistinretepa.it (Consip)
A17: Autenticazione | B17: SPID / CIE / CNS
A19: SCADENZE OPERATIVE
A20: Chiarimenti — termine invio | B20: 11/09/2026 (min. 19 gg prima scadenza offerte)
A21: Chiarimenti — risposte | B21: almeno 6 gg prima scadenza offerte
A22: 🔴 SCADENZA OFFERTE | B22: 30/09/2026 ore 16:00
A23: Prima seduta di gara | B23: 02/10/2026 ore 15:00 — INVERSIONE PROCEDIMENTALE
A24: Durata procedimento | B24: 9 mesi dalla pubblicazione bando in BDNCP
A25: Aggiudicazione stimata | B25: maggio-giugno 2027
A27: IMPORTI GLOBALI
A28: Importo base gara (IVA escl.) | B28: € 2.492.000.000
A29: Importo globale con opzioni | B29: € 3.289.440.000
A30: Incremento art. 120 c.1 lett. a) + c.9 | B30: + € 797.440.000 (32%)
A31: Commissione fornitore (Consip) | B31: 1,25% del fatturato
A32: Costi manodopera stimati | B32: 24% dell'importo (NON ribassabili)
A33: CCNL applicato | B33: CCNL Metalmeccanico (C011)
A34: Oneri sicurezza interferenze | B34: da quantificare in singolo Ordine di Fornitura
A36: STRUTTURA IN 5 LOTTI GEOGRAFICI
A37: LOTTO 1 | B37: CIG BCC72E2B3A — Val d'Aosta + Piemonte 1 (Città metrop. Torino). Volume 3.500.000 m³. Importo base 504.000.000 € / con opzioni 665.280.000 €. SOA OG11 IV bis + OG1 III bis. Cauzione 3.326.400 €. Costi manodopera 140.342.000 €. Fatturato richiesto 40.320.000 € (3/5 anni).
A38: LOTTO 2 | B38: CIG BCC72E3C0D — Piemonte 2 (tutte province escluse Torino). Volume 4.350.000 m³. Importo base 533.000.000 € / con opzioni 703.560.000 €. SOA OG11 IV + OG1 III. Cauzione 3.517.800 €. Costi manodopera 123.445.000 €. Fatturato richiesto 39.090.000 €.
A39: LOTTO 3 | B39: CIG BCC72E4CE0 — Provincia Autonoma Bolzano + Veneto 1 (Città metrop. Venezia, BL, TV, VI). Volume 7.600.000 m³. Importo base 598.000.000 € / con opzioni 789.360.000 €. SOA OG11 IV + OG1 III. Cauzione 3.946.800 €. Costi manodopera 146.389.000 €. Fatturato richiesto 35.880.000 €.
A40: LOTTO 4 | B40: CIG BCC72E5DB3 — Veneto 2 (VR, RO, PD). Volume 6.050.000 m³. Importo base 733.000.000 € / con opzioni 967.560.000 €. SOA OG11 V + OG1 IV. Cauzione 4.837.800 €. Costi manodopera 156.700.000 €. Fatturato richiesto 58.640.000 €.
A41: LOTTO 5 | B41: CIG BCC72E6E86 — Campania. Volume 1.500.000 m³. Importo base 124.000.000 € / con opzioni 163.680.000 €. SOA OG11 III + OG1 II. Cauzione 818.400 €. Costi manodopera 37.103.000 €. Fatturato richiesto 16.350.000 €. AQ con singolo operatore (gli altri lotti con più operatori).
A43: VINCOLI DI PARTECIPAZIONE
A44: Lotti 1-4 | B44: MAX 2 lotti per operatore (per rilevanza economica decrescente in caso di offerta a più)
A45: Lotto 5 | B45: Nessun vincolo lotti — Accordo Quadro con 1 solo operatore
A46: Blocco RTI | B46: In vigore per lotti 1-4: RTI/consorzio sempre stessa composizione
...

Sheet Multiservizio Lazio Ed4
A1: REGIONE LAZIO — MULTISERVIZIO TECNOLOGICO AASS ED. 4
A3: Aggiornamento scheda | B3: 10 settembre 2026 — bando pubblicato
A4: Stato | B4: 🔴 BANDO PUBBLICATO — offerte indicative 29/10/2026
A6: IDENTIFICAZIONE
A7: Ente aggiudicatore | B7: Regione Lazio — Direzione Centrale Acquisti (Soggetto Aggregatore per le Aziende Sanitarie del Lazio)
A8: Denominazione gara | B8: Gara comunitaria centralizzata a procedura aperta per il multiservizio tecnologico di manutenzione degli impianti relativi agli immobili in uso alle AASS Lazio — Ed. 4
A9: Tipo contratto | B9: EPC (Energy Performance Contract) — CAM EPC (DM 12/08/2024) + CAM Edilizia + CAM Pulizie
A10: Data disciplinare | B10: 12/06/2026
A11: Data progetto servizio | B11: 10/07/2026
A12: RUP | B12: Ing. Alessio Primavera — aprimavera@regione.lazio.it
A13: Doc. tecnici via email | B13: Planimetrie, bollette, diagnosi energetiche → ftrivisondoli@regione.lazio.it
A14: Piattaforma | B14: S.Tel.LA — https://centraleacquisti.regione.lazio.it
A15: Help desk piattaforma | B15: supporto.stella@regione.lazio.it — 06/997744 (lun-ven 9-13 / 14-18)
A16: Autenticazione | B16: SPID / CIE / CNS + firma digitale + PEC
A17: Riferimento normativo | B17: D.Lgs. 36/2023 (Codice contratti pubblici) e allegati
A19: SCADENZE OPERATIVE
A20: Data pubblicazione bando | B20: 12/06/2026 (disciplinare) — da verificare pubblicazione GUUE su S.Tel.LA
A21: 🔴 SCADENZA OFFERTE | B21: 29/10/2026 (indicativa da InfoGare — DA CONFERMARE su S.Tel.LA)
A22: Validità offerta | B22: 270 giorni dalla scadenza presentazione
A23: Sopralluogo obbligatorio | B23: Entro 30 giorni dalla scadenza offerte (richiesta via email all'AS)
A25: IMPORTI GLOBALI
A26: Importo base 108 mesi | B26: € 1.601.415.191,61 (IVA escl.)
A27: Oneri sicurezza interferenze | B27: € 98.000,00 (non soggetti a ribasso)
A28: Importo complessivo | B28: € 1.601.513.191,61 (IVA escl.)
A29: Valore globale con opzioni | B29: € 2.010.788.785,02
A30: di cui quinto d'obbligo | B30: € 320.302.638,32
A31: di cui proroga 6 mesi | B31: € 88.972.955,09
A32: Basi d'asta energia | B32: Spread elettrico 0,05000 €/kWh — Spread termico 0,02000 €/kWh — Acqua 3,00 €/m³
A33: Stime prezzo 2026 | B33: EE 0,22356 €/kWh — ET 0,06170 €/kWh — fattore 9,59 kWh/Sm³
A34: CCNL applicato | B34: CCNL C011 (Metalmeccanico) o equivalente (Allegato 7 se diverso)
A36: STRUTTURA IN 10 LOTTI (max 1 per operatore)
A37: LOTTO 1 | B37: A.O. S. Giovanni Addolorata + A.O.U. Sant'Andrea — importo base 221.168.519,46 € / con opz. 277.704.932,21 €. Cauzione 5.554.098,64 €. SOA OG1+OG11 classifica IV. Oneri interf. 12.400 €.
A38: LOTTO 2 | B38: ASL Roma 2 — importo base 219.327.828,75 € / con opz. 275.391.331,65 €. Cauzione 5.507.826,63 €. SOA IV. Oneri interf. 10.400 €.
A39: LOTTO 3 | B39: ASL Roma 1 — importo base 200.864.571,66 € / con opz. 252.209.686,64 €. Cauzione 5.044.193,73 €. SOA IV. Oneri interf. 10.400 €.
A40: LOTTO 4 | B40: ASL Frosinone — importo base 197.289.827,64 € / con opz. 247.721.396,93 €. Cauzione 4.954.427,94 €. SOA IV. Oneri interf. 10.400 €.
A41: LOTTO 5 | B41: ASL Roma 6 — importo base 149.718.371,40 € / con opz. 187.992.790,76 €. Cauzione 3.759.855,82 €. SOA III bis. Oneri interf. 10.400 €.
A42: LOTTO 6 | B42: ASL Latina — importo base 148.743.219,33 € / con opz. 186.768.433,16 €. Cauzione 3.735.368,66 €. SOA IV. Oneri interf. 10.400 €.
A43: LOTTO 7 | B43: ASL Roma 3 + ASL Roma 4 — importo base 125.567.749,80 € / con opz. 157.672.352,53 €. Cauzione 3.153.447,05 €. SOA III bis. Oneri interf. 12.000 €.
